2024-11-11 20:21:30.620 +02:00 [ERR] An error occurred while processing the request.
System.Exception: Test exception to log error
   at lr5.Controllers.HomeController.TriggerError() in D:\UNIVER\3_kurs_4s\ASP.NET\5\lr5\lr5\Controllers\HomeController.cs:line 33
   at lambda_method20(Closure, Object, Object[])
   at Microsoft.AspNetCore.Mvc.Infrastructure.ActionMethodExecutor.SyncActionResultExecutor.Execute(ActionContext actionContext, IActionResultTypeMapper mapper, ObjectMethodExecutor executor, Object controller, Object[] arguments)
   at Microsoft.AspNetCore.Mvc.Infrastructure.ControllerActionInvoker.InvokeActionMethodAsync()
   at Microsoft.AspNetCore.Mvc.Infrastructure.ControllerActionInvoker.Next(State& next, Scope& scope, Object& state, Boolean& isCompleted)
   at Microsoft.AspNetCore.Mvc.Infrastructure.ControllerActionInvoker.InvokeNextActionFilterAsync()
--- End of stack trace from previous location ---
   at Microsoft.AspNetCore.Mvc.Infrastructure.ControllerActionInvoker.Rethrow(ActionExecutedContextSealed context)
   at Microsoft.AspNetCore.Mvc.Infrastructure.ControllerActionInvoker.Next(State& next, Scope& scope, Object& state, Boolean& isCompleted)
   at Microsoft.AspNetCore.Mvc.Infrastructure.ControllerActionInvoker.InvokeInnerFilterAsync()
--- End of stack trace from previous location ---
   at Microsoft.AspNetCore.Mvc.Infrastructure.ResourceInvoker.<InvokeNextResourceFilter>g__Awaited|25_0(ResourceInvoker invoker, Task lastTask, State next, Scope scope, Object state, Boolean isCompleted)
   at Microsoft.AspNetCore.Mvc.Infrastructure.ResourceInvoker.Rethrow(ResourceExecutedContextSealed context)
   at Microsoft.AspNetCore.Mvc.Infrastructure.ResourceInvoker.Next(State& next, Scope& scope, Object& state, Boolean& isCompleted)
   at Microsoft.AspNetCore.Mvc.Infrastructure.ResourceInvoker.InvokeFilterPipelineAsync()
--- End of stack trace from previous location ---
   at Microsoft.AspNetCore.Mvc.Infrastructure.ResourceInvoker.<InvokeAsync>g__Awaited|17_0(ResourceInvoker invoker, Task task, IDisposable scope)
   at Microsoft.AspNetCore.Mvc.Infrastructure.ResourceInvoker.<InvokeAsync>g__Awaited|17_0(ResourceInvoker invoker, Task task, IDisposable scope)
   at lr5.Middleware.ErrorLoggingMiddleware.InvokeAsync(HttpContext context) in D:\UNIVER\3_kurs_4s\ASP.NET\5\lr5\lr5\Middleware\ErrorLoggingMiddleware.cs:line 24
2024-11-11 20:21:30.675 +02:00 [ERR] An unhandled exception has occurred while executing the request.
System.IO.IOException: The process cannot access the file 'D:\UNIVER\3_kurs_4s\ASP.NET\5\lr5\lr5\logs\error_log.txt' because it is being used by another process.
   at Microsoft.Win32.SafeHandles.SafeFileHandle.CreateFile(String fullPath, FileMode mode, FileAccess access, FileShare share, FileOptions options)
   at Microsoft.Win32.SafeHandles.SafeFileHandle.Open(String fullPath, FileMode mode, FileAccess access, FileShare share, FileOptions options, Int64 preallocationSize, Nullable`1 unixCreateMode)
   at System.IO.File.OpenHandle(String path, FileMode mode, FileAccess access, FileShare share, FileOptions options, Int64 preallocationSize)
   at System.IO.File.WriteToFileAsync(String path, FileMode mode, String contents, Encoding encoding, CancellationToken cancellationToken)
   at lr5.Middleware.ErrorLoggingMiddleware.InvokeAsync(HttpContext context) in D:\UNIVER\3_kurs_4s\ASP.NET\5\lr5\lr5\Middleware\ErrorLoggingMiddleware.cs:line 29
   at Microsoft.AspNetCore.Authorization.AuthorizationMiddleware.Invoke(HttpContext context)
   at Microsoft.AspNetCore.Authentication.AuthenticationMiddleware.Invoke(HttpContext context)
   at Microsoft.AspNetCore.Diagnostics.DeveloperExceptionPageMiddlewareImpl.Invoke(HttpContext context)
